Workbook

Sheet Dashboard
C1: Dashboard Keuangan Bulanan
A5: Bulan | L5: Total | M5: Nominal
A6: 45658 | L6: Pemasukan | M6: =IFERROR(__xludf.DUMMYFUNCTION("IFERROR(SUM(FILTER(Budgeting!K2:K1000, Budgeting!K2:K1000<>"""")), 0) "),9270000.0) -> 9270000 | P6: Total Pemasukan Per Kategori | Q6: Nominal | R6: Persentase
L7: Pengeluaran | M7: =SUM(Budgeting!E2:E1000) -> 8646900 | P7: Gaji | Q7: =SUMPRODUCT(Budgeting!$K$3:K1000,Budgeting!$L$3:L1000=P7) -> 4150000 | R7: =Q7/$M$7 -> 0.47994079
B8: Pemasukan | E8: Pengeluaran | H8: Sisa Uang | L8: Sisa Uang | M8: =M6-M7 -> 623100 | P8: Tunjangan | Q8: =SUMPRODUCT(Budgeting!$K$3:K1000,Budgeting!$L$3:L1000=P8) -> 3450000 | R8: =Q8/$M$7 -> 0.39898692
B9: =sumifs(Rangkuman!H:H, Rangkuman!F:F,A6) -> 5000000 | E9: =sumifs(Rangkuman!G:G, Rangkuman!F:F,A6) -> 5858900 | H9: =B9-E9 -> -858900 | L9: Total Pengeluaran Per Kategori | M9: Nominal | N9: Persentase | P9: Bonus | Q9: =SUMPRODUCT(Budgeting!$K$3:K1000,Budgeting!$L$3:L1000=P9) -> 620000 | R9: =Q9/$M$7 -> 0.071701997
L10: Tabungan | M10: =SUMPRODUCT(Budgeting!$E$3:E1000,Budgeting!$F$3:F1000=L10) -> 1208900 | N10: =M10/$M$7 -> 0.13980733 | P10: Hadiah | Q10: =SUMPRODUCT(Budgeting!$K$3:K1000,Budgeting!$L$3:L1000=P10) -> 350000 | R10: =Q10/$M$7 -> 0.040476934
D11: ALOKASI PENGELUARAN | L11: Kebutuhan | M11: =SUMPRODUCT(Budgeting!$E$3:E1000,Budgeting!$F$3:F1000=L11) -> 5710000 | N11: =M11/$M$7 -> 0.66035226 | P11: Penjualan | Q11: =SUMPRODUCT(Budgeting!$K$3:K1000,Budgeting!$L$3:L1000=P11) -> 350000 | R11: =Q11/$M$7 -> 0.040476934
L12: Keinginan | M12: =SUMPRODUCT(Budgeting!$E$3:E1000,Budgeting!$F$3:F1000=L12) -> 1728000 | N12: =M12/$M$7 -> 0.19984041 | P12: Sewa | Q12: =SUMPRODUCT(Budgeting!$K$3:K1000,Budgeting!$L$3:L1000=P12) -> 350000 | R12: =Q12/$M$7 -> 0.040476934
B13: Tabungan | E13: Kebutuhan | H13: Keinginan
B14: =SUMIFS(Budgeting!E:E, Budgeting!F:F, "Tabungan", Budgeting!H:H, $A$6) -> 1108900 | E14: =SUMIFS(Budgeting!E:E, Budgeting!F:F, "Kebutuhan", Budgeting!H:H, $A$6) -> 3810000 | H14: =SUMIFS(Budgeting!E:E, Budgeting!F:F, "Keinginan", Budgeting!H:H, $A$6) -> 940000
D16: ALOKASI PEMASUKAN
B18: Gaji | E18: Tunjangan | H18: Bonus
B19: =SUMIFS(Budgeting!K:K, Budgeting!L:L, "Gaji", Budgeting!N:N, $A$6) -> 2150000 | E19: =SUMIFS(Budgeting!K:K, Budgeting!L:L, "Tunjangan", Budgeting!N:N, $A$6) -> 1500000 | H19: =SUMIFS(Budgeting!K:K, Budgeting!L:L, "Bonus", Budgeting!N:N, $A$6) -> 300000 | L19: Forecast Pengeluaran Satu Hari Kedepan | M19: {=AVERAGE( INDEX(Rangkuman!R:R, MATCH(1E+100, Rangkuman!R:R)-1), INDEX(Rangkuman!R:R, MATCH(1E+100, Rangkuman!R:R)) )} -> 404450
L20: MA3 | M20: {=AVERAGE( INDEX(Rangkuman!R:R, MATCH(1E+100, Rangkuman!R:R)-2), INDEX(Rangkuman!R:R, MATCH(1E+100, Rangkuman!R:R)-1), INDEX(Rangkuman!R:R, MATCH(1E+100, Rangkuman!R:R)) )} -> 289633.33
B21: Hadiah | E21: Penjualan | H21: Sewa | L21: MA5 | M21: {=AVERAGE( INDEX(Rangkuman!R:R, MATCH(1E+100, Rangkuman!R:R)-4), INDEX(Rangkuman!R:R, MATCH(1E+100, Rangkuman!R:R)-3), INDEX(Rangkuman!R:R, MATCH(1E+100, Rangkuman!R:R)-2), INDEX(Rangkuman!R:R, MATCH(1E+100, Rangkuman!R:R)-1), INDEX(Rangkuman!R:R, MATCH(1E+100, Rangkuman!R:R)) )} -> 209780
B22: =SUMIFS(Budgeting!K:K, Budgeting!L:L, "Hadiah", Budgeting!N:N, $A$6) -> 350000 | E22: =SUMIFS(Budgeting!K:K, Budgeting!L:L, "Penjualan", Budgeting!N:N, $A$6) -> 350000 | H22: =SUMIFS(Budgeting!K:K, Budgeting!L:L, "Sewa", Budgeting!N:N, $A$6) -> 350000
A24: =IF(E9>B9,"Pengeluaran sudah melebihi pemasukan!", IF(E9>=0.9*B9,"Pengeluaran hampir mencapai total pemasukan. Coba lebih hemat!", "Keuangan dalam kondisi aman.")) -> Pengeluaran sudah melebihi pemasukan!
L25: Forecast Pemasukan Satu Hari Kedepan | M25: {=AVERAGE( INDEX(Rangkuman!S:S, MATCH(1E+100, Rangkuman!S:S)-1), INDEX(Rangkuman!S:S, MATCH(1E+100, Rangkuman!S:S)) )} -> 0
L26: MA3 | M26: {=AVERAGE( INDEX(Rangkuman!S:S, MATCH(1E+100, Rangkuman!S:S)-2), INDEX(Rangkuman!S:S, MATCH(1E+100, Rangkuman!S:S)-1), INDEX(Rangkuman!S:S, MATCH(1E+100, Rangkuman!S:S)) )} -> 0
L27: MA5 | M27: {=AVERAGE( INDEX(Rangkuman!S:S, MATCH(1E+100, Rangkuman!S:S)-4), INDEX(Rangkuman!S:S, MATCH(1E+100, Rangkuman!S:S)-3), INDEX(Rangkuman!S:S, MATCH(1E+100, Rangkuman!S:S)-2), INDEX(Rangkuman!S:S, MATCH(1E+100, Rangkuman!S:S)-1), INDEX(Rangkuman!S:S, MATCH(1E+100, Rangkuman!S:S)) )} -> 0
A42: =IF(AND(L19 > L20, L20 > L21), "Pengeluaran harian kamu terus naik. Sebaiknya mulai mengontrol pengeluaran dan sisihkan uang lebih.", IF(AND(L19 < L20, L20 < L21), "Pengeluaran kamu menurun dari hari ke hari. Pertahankan kebiasaan baik ini.", IF(L19 > L20, "Pengeluaran hari ini lebih besar dari rata-rata sebelumnya. Coba cek kembali apa yang meningkat.", IF(L19 < L20, "Pengeluaran hari ini lebih rendah dari biasanya. Ini waktu yang tepat untuk menabung lebih banyak.", "Pengeluaran stabil. Pertahankan pengelolaan keuangan seperti sekarang.")))) -> Pengeluaran kamu menurun dari hari ke hari. Pertahankan kebiasaan baik ini.
A44: =IF(AND(L25 > L26, L26 > L27), "Pemasukan kamu sedang meningkat secara konsisten. Pertahankan performa ini dan manfaatkan momentum untuk menambah sumber pemasukan.", IF(AND(L25 < L26, L26 < L27), "Pemasukan kamu menurun dari hari ke hari. Coba evaluasi penyebab penurunan dan cari peluang untuk meningkatkannya kembali.", IF(L25 > L26, "Pemasukan terbaru kamu lebih tinggi dari biasanya. Ini waktu yang baik untuk memperkuat strategi pemasukan.", IF(L25 < L26, "Pemasukan terbaru kamu lebih rendah dari rata-rata sebelumnya. Perlu diwaspadai dan mungkin perlu langkah perbaikan.", "Pemasukan kamu stabil. Pertahankan konsistensinya dan tetap cari peluang peningkatan.")))) -> Pemasukan kamu menurun dari hari ke hari. Coba evaluasi penyebab penurunan dan cari peluang untuk meningkatkannya kembali.

Sheet Budgeting
A1: Pengeluaran | J1: Pemasukan
A2: Tanggal | B2: Alokasi Pengeluaran | E2: Nominal | F2: Kategori | G2: Persentase | H2: Bulan | J2: Tanggal | K2: Nominal | L2: Kategori | M2: Persentase | N2: Bulan
A3: 45658 | B3: Tabungan utama | E3: 100000 | F3: Tabungan | G3: =E3/Dashboard!$M$7 -> 0.011564838 | H3: =IF(A3<>"", TEXT(A3, "mmmm yyyy"), "") -> January 2025 | J3: 45658 | K3: 850000 | L3: Gaji | M3: =K3/Dashboard!$M$7 -> 0.098301125 | N3: =IF(J3<>"", TEXT(J3, "mmmm yyyy"), "") -> January 2025
A4: 45659 | B4: Biaya makan bulanan | E4: 1000000 | F4: Kebutuhan | G4: =E4/Dashboard!$M$7 -> 0.11564838 | H4: =IF(A4<>"", TEXT(A4, "mmmm yyyy"), "") -> January 2025 | J4: 45659 | K4: 1300000 | L4: Gaji | M4: =K4/Dashboard!$M$7 -> 0.1503429 | N4: =IF(J4<>"", TEXT(J4, "mmmm yyyy"), "") -> January 2025
A5: 45660 | B5: Sewa kost | E5: 1300000 | F5: Kebutuhan | G5: =E5/Dashboard!$M$7 -> 0.1503429 | H5: =IF(A5<>"", TEXT(A5, "mmmm yyyy"), "") -> January 2025 | J5: 45660 | K5: 1000000 | L5: Tunjangan | M5: =K5/Dashboard!$M$7 -> 0.11564838 | N5: =IF(J5<>"", TEXT(J5, "mmmm yyyy"), "") -> January 2025
A6: 45661 | B6: Kebutuhan personal | E6: 300000 | F6: Kebutuhan | G6: =E6/Dashboard!$M$7 -> 0.034694515 | H6: =IF(A6<>"", TEXT(A6, "mmmm yyyy"), "") -> January 2025 | J6: 45661 | K6: 300000 | L6: Bonus | M6: =K6/Dashboard!$M$7 -> 0.034694515 | N6: =IF(J6<>"", TEXT(J6, "mmmm yyyy"), "") -> January 2025
A7: 45662 | B7: Simpanan dana darurat | E7: 350000 | F7: Tabungan | G7: =E7/Dashboard!$M$7 -> 0.040476934 | H7: =IF(A7<>"", TEXT(A7, "mmmm yyyy"), "") -> January 2025 | J7: 45662 | K7: 350000 | L7: Hadiah | M7: =K7/Dashboard!$M$7 -> 0.040476934 | N7: =IF(J7<>"", TEXT(J7, "mmmm yyyy"), "") -> January 2025
A8: 45663 | B8: Jajan | E8: 350000 | F8: Keinginan | G8: =E8/Dashboard!$M$7 -> 0.040476934 | H8: =IF(A8<>"", TEXT(A8, "mmmm yyyy"), "") -> January 2025 | J8: 45663 | K8: 350000 | L8: Penjualan | M8: =K8/Dashboard!$M$7 -> 0.040476934 | N8: =IF(J8<>"", TEXT(J8, "mmmm yyyy"), "") -> January 2025
A9: 45664 | B9: Untuk orang tua | E9: 500000 | F9: Keinginan | G9: =E9/Dashboard!$M$7 -> 0.057824191 | H9: =IF(A9<>"", TEXT(A9, "mmmm yyyy"), "") -> January 2025 | J9: 45664 | K9: 500000 | L9: Tunjangan | M9: =K9/Dashboard!$M$7 -> 0.057824191 | N9: =IF(J9<>"", TEXT(J9, "mmmm yyyy"), "") -> January 2025
A10: 45665 | B10: Biaya transport bulanan | E10: 350000 | F10: Kebutuhan | G10: =E10/Dashboard!$M$7 -> 0.040476934 | H10: =IF(A10<>"", TEXT(A10, "mmmm yyyy"), "") -> January 2025 | J10: 45665 | K10: 350000 | L10: Sewa | M10: =K10/Dashboard!$M$7 -> 0.040476934 | N10: =IF(J10<>"", TEXT(J10, "mmmm yyyy"), "") -> January 2025
A11: 45667 | B11: Apa Aja | E11: 60000 | F11: Kebutuhan | G11: =E11/Dashboard!$M$7 -> 0.006938903 | H11: =IF(A11<>"", TEXT(A11, "mmmm yyyy"), "") -> January 2025 | J11: 45689 | K11: 2000000 | L11: Gaji | M11: =K11/Dashboard!$M$7 -> 0.23129677 | N11: =IF(J11<>"", TEXT(J11, "mmmm yyyy"), "") -> February 2025
A12: 45668 | E12: 500000 | F12: Tabungan | G12: =E12/Dashboard!$M$7 -> 0.057824191 | H12: =IF(A12<>"", TEXT(A12, "mmmm yyyy"), "") -> January 2025 | J12: 45690 | K12: 1000000 | L12: Tunjangan | M12: =K12/Dashboard!$M$7 -> 0.11564838 | N12: =IF(J12<>"", TEXT(J12, "mmmm yyyy"), "") -> February 2025
A13: 45670 | B13: Apa AJa | E13: 90000 | F13: Keinginan | G13: =E13/Dashboard!$M$7 -> 0.010408354 | H13: =IF(A13<>"", TEXT(A13, "mmmm yyyy"), "") -> January 2025 | J13: 45696 | K13: 70000 | L13: Bonus | M13: =K13/Dashboard!$M$7 -> 0.0080953868 | N13: =IF(J13<>"", TEXT(J13, "mmmm yyyy"), "") -> February 2025
A14: 45671 | B14: apa aja | E14: 90000 | F14: Tabungan | G14: =E14/Dashboard!$M$7 -> 0.010408354 | H14: =IF(A14<>"", TEXT(A14, "mmmm yyyy"), "") -> January 2025 | J14: 45698 | K14: 250000 | L14: Bonus | M14: =K14/Dashboard!$M$7 -> 0.028912096 | N14: =IF(J14<>"", TEXT(J14, "mmmm yyyy"), "") -> February 2025
A15: 45673 | B15: apa aja | E15: 60000 | F15: Tabungan | G15: =E15/Dashboard!$M$7 -> 0.006938903 | H15: =IF(A15<>"", TEXT(A15, "mmmm yyyy"), "") -> January 2025 | J15: 45711 | K15: 950000 | L15: Tunjangan | M15: =K15/Dashboard!$M$7 -> 0.10986596 | N15: =IF(J15<>"", TEXT(J15, "mmmm yyyy"), "") -> February 2025
A16: 45675 | B16: apa aja | E16: 800000 | F16: Kebutuhan | G16: =E16/Dashboard!$M$7 -> 0.092518706 | H16: =IF(A16<>"", TEXT(A16, "mmmm yyyy"), "") -> January 2025 | M16: =K16/Dashboard!$M$7 -> 0 | N16: =IF(J16<>"", TEXT(J16, "mmmm yyyy"), "")
A17: 45680 | E17: 8900 | F17: Tabungan | G17: =E17/Dashboard!$M$7 -> 0.0010292706 | H17: =IF(A17<>"", TEXT(A17, "mmmm yyyy"), "") -> January 2025 | M17: =K17/Dashboard!$M$7 -> 0 | N17: =IF(J17<>"", TEXT(J17, "mmmm yyyy"), "")
A18: 45689 | B18: Tabungan utama | E18: 100000 | F18: Tabungan | G18: =E18/Dashboard!$M$7 -> 0.011564838 | H18: =IF(A18<>"", TEXT(A18, "mmmm yyyy"), "") -> February 2025 | M18: =K18/Dashboard!$M$7 -> 0 | N18: =IF(J18<>"", TEXT(J18, "mmmm yyyy"), "")
A19: 45690 | B19: Beli sepatu | E19: 780000 | F19: Keinginan | G19: =E19/Dashboard!$M$7 -> 0.090205738 | H19: =IF(A19<>"", TEXT(A19, "mmmm yyyy"), "") -> February 2025 | M19: =K19/Dashboard!$M$7 -> 0 | N19: =IF(J19<>"", TEXT(J19, "mmmm yyyy"), "")
A20: 45691 | B20: Biaya makan bulanan | E20: 1000000 | F20: Kebutuhan | G20: =E20/Dashboard!$M$7 -> 0.11564838 | H20: =IF(A20<>"", TEXT(A20, "mmmm yyyy"), "") -> February 2025 | M20: =K20/Dashboard!$M$7 -> 0 | N20: =IF(J20<>"", TEXT(J20, "mmmm yyyy"), "")
A21: 45702 | B21: Servis kendaraan | E21: 400000 | F21: Kebutuhan | G21: =E21/Dashboard!$M$7 -> 0.046259353 | H21: =IF(A21<>"", TEXT(A21, "mmmm yyyy"), "") -> February 2025 | M21: =K21/Dashboard!$M$7 -> 0 | N21: =IF(J21<>"", TEXT(J21, "mmmm yyyy"), "")
A22: 45703 | B22: Apa aja | E22: 500000 | F22: Kebutuhan | G22: =E22/Dashboard!$M$7 -> 0.057824191 | H22: =IF(A22<>"", TEXT(A22, "mmmm yyyy"), "") -> February 2025 | M22: =K22/Dashboard!$M$7 -> 0 | N22: =IF(J22<>"", TEXT(J22, "mmmm yyyy"), "")
A23: 45732 | B23: apa aja | E23: 8000 | F23: Keinginan | G23: =E23/Dashboard!$M$7 -> 0.00092518706 | H23: =IF(A23<>"", TEXT(A23, "mmmm yyyy"), "") -> March 2025 | M23: =K23/Dashboard!$M$7 -> 0 | N23: =IF(J23<>"", TEXT(J23, "mmmm yyyy"), "")
G24: =E24/Dashboard!$M$7 -> 0 | H24: =IF(A24<>"", TEXT(A24, "mmmm yyyy"), "") | M24: =K24/Dashboard!$M$7 -> 0 | N24: =IF(J24<>"", TEXT(J24, "mmmm yyyy"), "")
G25: =E25/Dashboard!$M$7 -> 0 | H25: =IF(A25<>"", TEXT(A25, "mmmm yyyy"), "") | M25: =K25/Dashboard!$M$7 -> 0 | N25: =IF(J25<>"", TEXT(J25, "mmmm yyyy"), "")
G26: =E26/Dashboard!$M$7 -> 0 | H26: =IF(A26<>"", TEXT(A26, "mmmm yyyy"), "") | M26: =K26/Dashboard!$M$7 -> 0 | N26: =IF(J26<>"", TEXT(J26, "mmmm yyyy"), "")
G27: =E27/Dashboard!$M$7 -> 0 | H27: =IF(A27<>"", TEXT(A27, "mmmm yyyy"), "") | M27: =K27/Dashboard!$M$7 -> 0 | N27: =IF(J27<>"", TEXT(J27, "mmmm yyyy"), "")
G28: =E28/Dashboard!$M$7 -> 0 | H28: =IF(A28<>"", TEXT(A28, "mmmm yyyy"), "") | M28: =K28/Dashboard!$M$7 -> 0 | N28: =IF(J28<>"", TEXT(J28, "mmmm yyyy"), "")
G29: =E29/Dashboard!$M$7 -> 0 | H29: =IF(A29<>"", TEXT(A29, "mmmm yyyy"), "") | M29: =K29/Dashboard!$M$7 -> 0 | N29: =IF(J29<>"", TEXT(J29, "mmmm yyyy"), "")
G30: =E30/Dashboard!$M$7 -> 0 | H30: =IF(A30<>"", TEXT(A30, "mmmm yyyy"), "") | M30: =K30/Dashboard!$M$7 -> 0 | N30: =IF(J30<>"", TEXT(J30, "mmmm yyyy"), "")
G31: =E31/Dashboard!$M$7 -> 0 | H31: =IF(A31<>"", TEXT(A31, "mmmm yyyy"), "") | M31: =K31/Dashboard!$M$7 -> 0 | N31: =IF(J31<>"", TEXT(J31, "mmmm yyyy"), "")
G32: =E32/Dashboard!$M$7 -> 0 | H32: =IF(A32<>"", TEXT(A32, "mmmm yyyy"), "") | M32: =K32/Dashboard!$M$7 -> 0 | N32: =IF(J32<>"", TEXT(J32, "mmmm yyyy"), "")
G33: =E33/Dashboard!$M$7 -> 0 | H33: =IF(A33<>"", TEXT(A33, "mmmm yyyy"), "") | M33: =K33/Dashboard!$M$7 -> 0 | N33: =IF(J33<>"", TEXT(J33, "mmmm yyyy"), "")
G34: =E34/Dashboard!$M$7 -> 0 | H34: =IF(A34<>"", TEXT(A34, "mmmm yyyy"), "") | M34: =K34/Dashboard!$M$7 -> 0 | N34: =IF(J34<>"", TEXT(J34, "mmmm yyyy"), "")
G35: =E35/Dashboard!$M$7 -> 0 | H35: =IF(A35<>"", TEXT(A35, "mmmm yyyy"), "") | M35: =K35/Dashboard!$M$7 -> 0 | N35: =IF(J35<>"", TEXT(J35, "mmmm yyyy"), "")
... G210: =E210/Dashboard!$M$7 -> 0 | H210: =IF(A210<>"", TEXT(A210, "mmmm yyyy"), "") | M210: =K210/Dashboard!$M$7 -> 0 | N210: =IF(J210<>"", TEXT(J210, "mmmm yyyy"), "")

Sheet Rangkuman
A1: Tanggal | B1: Pengeluaran | C1: Pemasukan | G1: Pengeluaran | H1: Pemasukan | I1: Pemasukan | K1: Kategori | L1: Nominal | N1: Kategori | O1: Nominal | Q1: Bulan | R1: Pengeluaran | S1: Pemasukan
A2: {=SORT(UNIQUE({Budgeting!A3:A1000; Budgeting!J3:J1000}))} -> 45658 | B2: {=IF(A2:A1000="",,SUMIF(Budgeting!A3:A1000, A2:A1000, Budgeting!E3:E1000))} -> 100000 | C2: {=IF(A2:A1000="",,SUMIF(Budgeting!J3:J1000, A2:A1000, Budgeting!K3:K1000))} -> 850000 | F2: =IFERROR(__xludf.DUMMYFUNCTION("SORT( UNIQUE( FILTER(TEXT(A2:A1000,""mmmm yyyy""), A2:A1000<>"""") ), MATCH(UNIQUE(FILTER(TEXT(A2:A1000,""mmmm yyyy""), A2:A1000<>"""")), TEXT(SORT(UNIQUE(A2:A1000)), ""mmmm yyyy""), 0), TRUE ) "),"January 2025") -> January 2025 | G2: {=IF(F2:F1000="",,SUMIF(TEXT(A:A,"mmmm yyyy"), F2:F1000, B:B))} -> 5858900 | H2: {=IF(F2:F1000="",,SUMIF(TEXT(A:A,"mmmm yyyy"), F2:F1000, C:C))} -> 5000000 | K2: Tabungan | L2: =SUMIFS(Budgeting!E:E, Budgeting!F:F, "Tabungan", Budgeting!H:H, Dashboard!$A$6) -> 1108900 | N2: Gaji | O2: =SUMIFS(Budgeting!K:K, Budgeting!L:L, "Gaji", Budgeting!N:N, Dashboard!$A$6) -> 2150000 | Q2: {=IF(A2:A1000="",, TEXT(A2:A1000, "mmmm yyyy"))} -> January 2025 | R2: =IF(LOWER(TRIM($Q2)) = LOWER(TRIM(Dashboard!$A$6)), B2, "") -> 100000 | S2: =IF(LOWER(TRIM($Q2)) = LOWER(TRIM(Dashboard!$A$6)), C2, "") -> 850000 | T2: =IF(LOWER(TRIM(TEXT($Q2, "mmmm yyyy"))) = LOWER(TRIM(Dashboard!$A$6)), A2:A1000, "") -> 45658
A3: 45659 | B3: 1000000 | C3: 1300000 | F3: =IFERROR(__xludf.DUMMYFUNCTION("""COMPUTED_VALUE"""),"February 2025") -> February 2025 | G3: 2780000 | H3: 4270000 | K3: Kebutuhan | L3: =SUMIFS(Budgeting!E:E, Budgeting!F:F, "Kebutuhan", Budgeting!H:H, Dashboard!$A$6) -> 3810000 | N3: Tunjangan | O3: =SUMIFS(Budgeting!K:K, Budgeting!L:L, "Tunjangan", Budgeting!N:N, Dashboard!$A$6) -> 1500000 | Q3: January 2025 | R3: =IF(LOWER(TRIM($Q3)) = LOWER(TRIM(Dashboard!$A$6)), B3, "") -> 1000000 | S3: =IF(LOWER(TRIM($Q3)) = LOWER(TRIM(Dashboard!$A$6)), C3, "") -> 1300000 | T3: =IF(LOWER(TRIM(TEXT($Q3, "mmmm yyyy"))) = LOWER(TRIM(Dashboard!$A$6)), A3:A1000, "") -> 45659
A4: 45660 | B4: 1300000 | C4: 1000000 | F4: =IFERROR(__xludf.DUMMYFUNCTION("""COMPUTED_VALUE"""),"March 2025") -> March 2025 | G4: 8000 | H4: 0 | K4: Keinginan | L4: =SUMIFS(Budgeting!E:E, Budgeting!F:F, "Keinginan", Budgeting!H:H, Dashboard!$A$6) -> 940000 | N4: Bonus | O4: =SUMIFS(Budgeting!K:K, Budgeting!L:L, "Bonus", Budgeting!N:N, Dashboard!$A$6) -> 300000 | Q4: January 2025 | R4: =IF(LOWER(TRIM($Q4)) = LOWER(TRIM(Dashboard!$A$6)), B4, "") -> 1300000 | S4: =IF(LOWER(TRIM($Q4)) = LOWER(TRIM(Dashboard!$A$6)), C4, "") -> 1000000 | T4: =IF(LOWER(TRIM(TEXT($Q4, "mmmm yyyy"))) = LOWER(TRIM(Dashboard!$A$6)), A4:A1000, "") -> 45660
A5: 45661 | B5: 300000 | C5: 300000 | N5: Hadiah | O5: =SUMIFS(Budgeting!K:K, Budgeting!L:L, "Hadiah", Budgeting!N:N, Dashboard!$A$6) -> 350000 | Q5: January 2025 | R5: =IF(LOWER(TRIM($Q5)) = LOWER(TRIM(Dashboard!$A$6)), B5, "") -> 300000 | S5: =IF(LOWER(TRIM($Q5)) = LOWER(TRIM(Dashboard!$A$6)), C5, "") -> 300000 | T5: =IF(LOWER(TRIM(TEXT($Q5, "mmmm yyyy"))) = LOWER(TRIM(Dashboard!$A$6)), A5:A1000, "") -> 45661
A6: 45662 | B6: 350000 | C6: 350000 | N6: Penjualan | O6: =SUMIFS(Budgeting!K:K, Budgeting!L:L, "Penjualan", Budgeting!N:N, Dashboard!$A$6) -> 350000 | Q6: January 2025 | R6: =IF(LOWER(TRIM($Q6)) = LOWER(TRIM(Dashboard!$A$6)), B6, "") -> 350000 | S6: =IF(LOWER(TRIM($Q6)) = LOWER(TRIM(Dashboard!$A$6)), C6, "") -> 350000 | T6: =IF(LOWER(TRIM(TEXT($Q6, "mmmm yyyy"))) = LOWER(TRIM(Dashboard!$A$6)), A6:A1000, "") -> 45662
A7: 45663 | B7: 350000 | C7: 350000 | N7: Sewa | O7: =SUMIFS(Budgeting!K:K, Budgeting!L:L, "Sewa", Budgeting!N:N, Dashboard!$A$6) -> 350000 | Q7: January 2025 | R7: =IF(LOWER(TRIM($Q7)) = LOWER(TRIM(Dashboard!$A$6)), B7, "") -> 350000 | S7: =IF(LOWER(TRIM($Q7)) = LOWER(TRIM(Dashboard!$A$6)), C7, "") -> 350000 | T7: =IF(LOWER(TRIM(TEXT($Q7, "mmmm yyyy"))) = LOWER(TRIM(Dashboard!$A$6)), A7:A1000, "") -> 45663
A8: 45664 | B8: 500000 | C8: 500000 | Q8: January 2025 | R8: =IF(LOWER(TRIM($Q8)) = LOWER(TRIM(Dashboard!$A$6)), B8, "") -> 500000 | S8: =IF(LOWER(TRIM($Q8)) = LOWER(TRIM(Dashboard!$A$6)), C8, "") -> 500000 | T8: =IF(LOWER(TRIM(TEXT($Q8, "mmmm yyyy"))) = LOWER(TRIM(Dashboard!$A$6)), A8:A1000, "") -> 45664
A9: 45665 | B9: 350000 | C9: 350000 | Q9: January 2025 | R9: =IF(LOWER(TRIM($Q9)) = LOWER(TRIM(Dashboard!$A$6)), B9, "") -> 350000 | S9: =IF(LOWER(TRIM($Q9)) = LOWER(TRIM(Dashboard!$A$6)), C9, "") -> 350000 | T9: =IF(LOWER(TRIM(TEXT($Q9, "mmmm yyyy"))) = LOWER(TRIM(Dashboard!$A$6)), A9:A1000, "") -> 45665
A10: 45667 | B10: 60000 | C10: 0 | Q10: January 2025 | R10: =IF(LOWER(TRIM($Q10)) = LOWER(TRIM(Dashboard!$A$6)), B10, "") -> 60000 | S10: =IF(LOWER(TRIM($Q10)) = LOWER(TRIM(Dashboard!$A$6)), C10, "") -> 0 | T10: =IF(LOWER(TRIM(TEXT($Q10, "mmmm yyyy"))) = LOWER(TRIM(Dashboard!$A$6)), A10:A1000, "") -> 45667
A11: 45668 | B11: 500000 | C11: 0 | Q11: January 2025 | R11: =IF(LOWER(TRIM($Q11)) = LOWER(TRIM(Dashboard!$A$6)), B11, "") -> 500000 | S11: =IF(LOWER(TRIM($Q11)) = LOWER(TRIM(Dashboard!$A$6)), C11, "") -> 0 | T11: =IF(LOWER(TRIM(TEXT($Q11, "mmmm yyyy"))) = LOWER(TRIM(Dashboard!$A$6)), A11:A1000, "") -> 45668
A12: 45670 | B12: 90000 | C12: 0 | Q12: January 2025 | R12: =IF(LOWER(TRIM($Q12)) = LOWER(TRIM(Dashboard!$A$6)), B12, "") -> 90000 | S12: =IF(LOWER(TRIM($Q12)) = LOWER(TRIM(Dashboard!$A$6)), C12, "") -> 0 | T12: =IF(LOWER(TRIM(TEXT($Q12, "mmmm yyyy"))) = LOWER(TRIM(Dashboard!$A$6)), A12:A1000, "") -> 45670
A13: 45671 | B13: 90000 | C13: 0 | E13: {=IF(A13<>"", UNIQUE(TEXT(A13, "mmmm yyyy")), "")} -> January 2025 | Q13: January 2025 | R13: =IF(LOWER(TRIM($Q13)) = LOWER(TRIM(Dashboard!$A$6)), B13, "") -> 90000 | S13: =IF(LOWER(TRIM($Q13)) = LOWER(TRIM(Dashboard!$A$6)), C13, "") -> 0 | T13: =IF(LOWER(TRIM(TEXT($Q13, "mmmm yyyy"))) = LOWER(TRIM(Dashboard!$A$6)), A13:A1000, "") -> 45671
A14: 45673 | B14: 60000 | C14: 0 | E14: =IF(A14<>"", TEXT(A14, "mmmm yyyy"), "") -> January 2025 | Q14: January 2025 | R14: =IF(LOWER(TRIM($Q14)) = LOWER(TRIM(Dashboard!$A$6)), B14, "") -> 60000 | S14: =IF(LOWER(TRIM($Q14)) = LOWER(TRIM(Dashboard!$A$6)), C14, "") -> 0 | T14: =IF(LOWER(TRIM(TEXT($Q14, "mmmm yyyy"))) = LOWER(TRIM(Dashboard!$A$6)), A14:A1000, "") -> 45673
A15: 45675 | B15: 800000 | C15: 0 | E15: =IF(A15<>"", TEXT(A15, "mmmm yyyy"), "") -> January 2025 | J15: JANGAN DIUBAH !!!! | Q15: January 2025 | R15: =IF(LOWER(TRIM($Q15)) = LOWER(TRIM(Dashboard!$A$6)), B15, "") -> 800000 | S15: =IF(LOWER(TRIM($Q15)) = LOWER(TRIM(Dashboard!$A$6)), C15, "") -> 0 | T15: =IF(LOWER(TRIM(TEXT($Q15, "mmmm yyyy"))) = LOWER(TRIM(Dashboard!$A$6)), A15:A1000, "") -> 45675
A16: 45680 | B16: 8900 | C16: 0 | E16: =IF(A16<>"", TEXT(A16, "mmmm yyyy"), "") -> January 2025 | Q16: January 2025 | R16: =IF(LOWER(TRIM($Q16)) = LOWER(TRIM(Dashboard!$A$6)), B16, "") -> 8900 | S16: =IF(LOWER(TRIM($Q16)) = LOWER(TRIM(Dashboard!$A$6)), C16, "") -> 0 | T16: =IF(LOWER(TRIM(TEXT($Q16, "mmmm yyyy"))) = LOWER(TRIM(Dashboard!$A$6)), A16:A1000, "") -> 45680
A17: 45689 | B17: 100000 | C17: 2000000 | E17: =IF(A17<>"", TEXT(A17, "mmmm yyyy"), "") -> February 2025 | Q17: February 2025 | R17: =IF(LOWER(TRIM($Q17)) = LOWER(TRIM(Dashboard!$A$6)), B17, "") | S17: =IF(LOWER(TRIM($Q17)) = LOWER(TRIM(Dashboard!$A$6)), C17, "") | T17: =IF(LOWER(TRIM(TEXT($Q17, "mmmm yyyy"))) = LOWER(TRIM(Dashboard!$A$6)), A17:A1000, "")
A18: 45690 | B18: 780000 | C18: 1000000 | E18: =IF(A18<>"", TEXT(A18, "mmmm yyyy"), "") -> February 2025 | Q18: February 2025 | R18: =IF(LOWER(TRIM($Q18)) = LOWER(TRIM(Dashboard!$A$6)), B18, "") | S18: =IF(LOWER(TRIM($Q18)) = LOWER(TRIM(Dashboard!$A$6)), C18, "") | T18: =IF(LOWER(TRIM(TEXT($Q18, "mmmm yyyy"))) = LOWER(TRIM(Dashboard!$A$6)), A18:A1000, "")
A19: 45691 | B19: 1000000 | C19: 0 | E19: =IF(A19<>"", TEXT(A19, "mmmm yyyy"), "") -> February 2025 | Q19: February 2025 | R19: =IF(LOWER(TRIM($Q19)) = LOWER(TRIM(Dashboard!$A$6)), B19, "") | S19: =IF(LOWER(TRIM($Q19)) = LOWER(TRIM(Dashboard!$A$6)), C19, "") | T19: =IF(LOWER(TRIM(TEXT($Q19, "mmmm yyyy"))) = LOWER(TRIM(Dashboard!$A$6)), A19:A1000, "")
A20: 45696 | B20: 0 | C20: 70000 | E20: =IF(A20<>"", TEXT(A20, "mmmm yyyy"), "") -> February 2025 | Q20: February 2025 | R20: =IF(LOWER(TRIM($Q20)) = LOWER(TRIM(Dashboard!$A$6)), B20, "") | S20: =IF(LOWER(TRIM($Q20)) = LOWER(TRIM(Dashboard!$A$6)), C20, "") | T20: =IF(LOWER(TRIM(TEXT($Q20, "mmmm yyyy"))) = LOWER(TRIM(Dashboard!$A$6)), A20:A1000, "")
A21: 45698 | B21: 0 | C21: 250000 | E21: =IF(A21<>"", TEXT(A21, "mmmm yyyy"), "") -> February 2025 | Q21: February 2025 | R21: =IF(LOWER(TRIM($Q21)) = LOWER(TRIM(Dashboard!$A$6)), B21, "") | S21: =IF(LOWER(TRIM($Q21)) = LOWER(TRIM(Dashboard!$A$6)), C21, "") | T21: =IF(LOWER(TRIM(TEXT($Q21, "mmmm yyyy"))) = LOWER(TRIM(Dashboard!$A$6)), A21:A1000, "")
A22: 45702 | B22: 400000 | C22: 0 | E22: =IF(A22<>"", TEXT(A22, "mmmm yyyy"), "") -> February 2025 | Q22: February 2025 | R22: =IF(LOWER(TRIM($Q22)) = LOWER(TRIM(Dashboard!$A$6)), B22, "") | S22: =IF(LOWER(TRIM($Q22)) = LOWER(TRIM(Dashboard!$A$6)), C22, "") | T22: =IF(LOWER(TRIM(TEXT($Q22, "mmmm yyyy"))) = LOWER(TRIM(Dashboard!$A$6)), A22:A1000, "")
A23: 45703 | B23: 500000 | C23: 0 | E23: =IF(A23<>"", TEXT(A23, "mmmm yyyy"), "") -> February 2025 | Q23: February 2025 | R23: =IF(LOWER(TRIM($Q23)) = LOWER(TRIM(Dashboard!$A$6)), B23, "") | S23: =IF(LOWER(TRIM($Q23)) = LOWER(TRIM(Dashboard!$A$6)), C23, "") | T23: =IF(LOWER(TRIM(TEXT($Q23, "mmmm yyyy"))) = LOWER(TRIM(Dashboard!$A$6)), A23:A1000, "")
A24: 45711 | B24: 0 | C24: 950000 | E24: =IF(A24<>"", TEXT(A24, "mmmm yyyy"), "") -> February 2025 | Q24: February 2025 | R24: =IF(LOWER(TRIM($Q24)) = LOWER(TRIM(Dashboard!$A$6)), B24, "") | S24: =IF(LOWER(TRIM($Q24)) = LOWER(TRIM(Dashboard!$A$6)), C24, "") | T24: =IF(LOWER(TRIM(TEXT($Q24, "mmmm yyyy"))) = LOWER(TRIM(Dashboard!$A$6)), A24:A1000, "")
A25: 45732 | B25: 8000 | C25: 0 | E25: =IF(A25<>"", TEXT(A25, "mmmm yyyy"), "") -> March 2025 | Q25: March 2025 | R25: =IF(LOWER(TRIM($Q25)) = LOWER(TRIM(Dashboard!$A$6)), B25, "") | S25: =IF(LOWER(TRIM($Q25)) = LOWER(TRIM(Dashboard!$A$6)), C25, "") | T25: =IF(LOWER(TRIM(TEXT($Q25, "mmmm yyyy"))) = LOWER(TRIM(Dashboard!$A$6)), A25:A1000, "")
E26: =IF(A26<>"", TEXT(A26, "mmmm yyyy"), "") | R26: =IF(LOWER(TRIM($Q26)) = LOWER(TRIM(Dashboard!$A$6)), B26, "") | S26: =IF(LOWER(TRIM($Q26)) = LOWER(TRIM(Dashboard!$A$6)), C26, "") | T26: =IF(LOWER(TRIM(TEXT($Q26, "mmmm yyyy"))) = LOWER(TRIM(Dashboard!$A$6)), A26:A1000, "")
E27: =IF(A27<>"", TEXT(A27, "mmmm yyyy"), "") | R27: =IF(LOWER(TRIM($Q27)) = LOWER(TRIM(Dashboard!$A$6)), B27, "") | S27: =IF(LOWER(TRIM($Q27)) = LOWER(TRIM(Dashboard!$A$6)), C27, "") | T27: =IF(LOWER(TRIM(TEXT($Q27, "mmmm yyyy"))) = LOWER(TRIM(Dashboard!$A$6)), A27:A1000, "")
E28: =IF(A28<>"", TEXT(A28, "mmmm yyyy"), "") | R28: =IF(LOWER(TRIM($Q28)) = LOWER(TRIM(Dashboard!$A$6)), B28, "") | S28: =IF(LOWER(TRIM($Q28)) = LOWER(TRIM(Dashboard!$A$6)), C28, "") | T28: =IF(LOWER(TRIM(TEXT($Q28, "mmmm yyyy"))) = LOWER(TRIM(Dashboard!$A$6)), A28:A1000, "")
E29: =IF(A29<>"", TEXT(A29, "mmmm yyyy"), "") | R29: =IF(LOWER(TRIM($Q29)) = LOWER(TRIM(Dashboard!$A$6)), B29, "") | S29: =IF(LOWER(TRIM($Q29)) = LOWER(TRIM(Dashboard!$A$6)), C29, "") | T29: =IF(LOWER(TRIM(TEXT($Q29, "mmmm yyyy"))) = LOWER(TRIM(Dashboard!$A$6)), A29:A1000, "")
E30: =IF(A30<>"", TEXT(A30, "mmmm yyyy"), "") | R30: =IF(LOWER(TRIM($Q30)) = LOWER(TRIM(Dashboard!$A$6)), B30, "") | S30: =IF(LOWER(TRIM($Q30)) = LOWER(TRIM(Dashboard!$A$6)), C30, "") | T30: =IF(LOWER(TRIM(TEXT($Q30, "mmmm yyyy"))) = LOWER(TRIM(Dashboard!$A$6)), A30:A1000, "")
E31: =IF(A31<>"", TEXT(A31, "mmmm yyyy"), "") | R31: =IF(LOWER(TRIM($Q31)) = LOWER(TRIM(Dashboard!$A$6)), B31, "") | S31: =IF(LOWER(TRIM($Q31)) = LOWER(TRIM(Dashboard!$A$6)), C31, "") | T31: =IF(LOWER(TRIM(TEXT($Q31, "mmmm yyyy"))) = LOWER(TRIM(Dashboard!$A$6)), A31:A1000, "")
E32: =IF(A32<>"", TEXT(A32, "mmmm yyyy"), "") | R32: =IF(LOWER(TRIM($Q32)) = LOWER(TRIM(Dashboard!$A$6)), B32, "") | S32: =IF(LOWER(TRIM($Q32)) = LOWER(TRIM(Dashboard!$A$6)), C32, "") | T32: =IF(LOWER(TRIM(TEXT($Q32, "mmmm yyyy"))) = LOWER(TRIM(Dashboard!$A$6)), A32:A1000, "")
E33: =IF(A33<>"", TEXT(A33, "mmmm yyyy"), "") | R33: =IF(LOWER(TRIM($Q33)) = LOWER(TRIM(Dashboard!$A$6)), B33, "") | S33: =IF(LOWER(TRIM($Q33)) = LOWER(TRIM(Dashboard!$A$6)), C33, "") | T33: =IF(LOWER(TRIM(TEXT($Q33, "mmmm yyyy"))) = LOWER(TRIM(Dashboard!$A$6)), A33:A1000, "")
E34: =IF(A34<>"", TEXT(A34, "mmmm yyyy"), "") | R34: =IF(LOWER(TRIM($Q34)) = LOWER(TRIM(Dashboard!$A$6)), B34, "") | S34: =IF(LOWER(TRIM($Q34)) = LOWER(TRIM(Dashboard!$A$6)), C34, "") | T34: =IF(LOWER(TRIM(TEXT($Q34, "mmmm yyyy"))) = LOWER(TRIM(Dashboard!$A$6)), A34:A1000, "")
E35: =IF(A35<>"", TEXT(A35, "mmmm yyyy"), "") | R35: =IF(LOWER(TRIM($Q35)) = LOWER(TRIM(Dashboard!$A$6)), B35, "") | S35: =IF(LOWER(TRIM($Q35)) = LOWER(TRIM(Dashboard!$A$6)), C35, "") | T35: =IF(LOWER(TRIM(TEXT($Q35, "mmmm yyyy"))) = LOWER(TRIM(Dashboard!$A$6)), A35:A1000, "")
E36: =IF(A36<>"", TEXT(A36, "mmmm yyyy"), "") | R36: =IF(LOWER(TRIM($Q36)) = LOWER(TRIM(Dashboard!$A$6)), B36, "") | S36: =IF(LOWER(TRIM($Q36)) = LOWER(TRIM(Dashboard!$A$6)), C36, "") | T36: =IF(LOWER(TRIM(TEXT($Q36, "mmmm yyyy"))) = LOWER(TRIM(Dashboard!$A$6)), A36:A1000, "")
E37: =IF(A37<>"", TEXT(A37, "mmmm yyyy"), "") | R37: =IF(LOWER(TRIM($Q37)) = LOWER(TRIM(Dashboard!$A$6)), B37, "") | S37: =IF(LOWER(TRIM($Q37)) = LOWER(TRIM(Dashboard!$A$6)), C37, "") | T37: =IF(LOWER(TRIM(TEXT($Q37, "mmmm yyyy"))) = LOWER(TRIM(Dashboard!$A$6)), A37:A1000, "")
E38: =IF(A38<>"", TEXT(A38, "mmmm yyyy"), "") | R38: =IF(LOWER(TRIM($Q38)) = LOWER(TRIM(Dashboard!$A$6)), B38, "") | S38: =IF(LOWER(TRIM($Q38)) = LOWER(TRIM(Dashboard!$A$6)), C38, "") | T38: =IF(LOWER(TRIM(TEXT($Q38, "mmmm yyyy"))) = LOWER(TRIM(Dashboard!$A$6)), A38:A1000, "")
E39: =IF(A39<>"", TEXT(A39, "mmmm yyyy"), "") | R39: =IF(LOWER(TRIM($Q39)) = LOWER(TRIM(Dashboard!$A$6)), B39, "") | S39: =IF(LOWER(TRIM($Q39)) = LOWER(TRIM(Dashboard!$A$6)), C39, "") | T39: =IF(LOWER(TRIM(TEXT($Q39, "mmmm yyyy"))) = LOWER(TRIM(Dashboard!$A$6)), A39:A1000, "")
E40: =IF(A40<>"", TEXT(A40, "mmmm yyyy"), "") | R40: =IF(LOWER(TRIM($Q40)) = LOWER(TRIM(Dashboard!$A$6)), B40, "") | S40: =IF(LOWER(TRIM($Q40)) = LOWER(TRIM(Dashboard!$A$6)), C40, "") | T40: =IF(LOWER(TRIM(TEXT($Q40, "mmmm yyyy"))) = LOWER(TRIM(Dashboard!$A$6)), A40:A1000, "")
...
